Workbook

Sheet Análisis de Asistencia
A1: Análisis de Asistencia — 10 días
B3: Día 1 | C3: Día 2 | D3: Día 3 | E3: Día 4 | F3: Día 5 | G3: Día 6 | H3: Día 7 | I3: Día 8 | J3: Día 9 | K3: Día 10 | L3: Total | M3: Total
A4: Inscrito en plataforma | B4: 46175 | C4: 46176 | D4: 46177 | E4: 46182 | F4: 46189 | G4: 46190 | H4: 46191 | I4: 46196 | J4: 46197 | K4: 46198 | L4: Asistencias | M4: Fallas
A5: juan manuel anzola lagos | B5: =IF(COUNTIFS('Respuestas de formulario 1'!$D:$D,B$4,'Respuestas de formulario 1'!$E:$E,$A5)>0,1,0) -> 0 | C5: =IF(COUNTIFS('Respuestas de formulario 1'!$D:$D,C$4,'Respuestas de formulario 1'!$E:$E,$A5)>0,1,0) -> 1 | D5: =IF(COUNTIFS('Respuestas de formulario 1'!$D:$D,D$4,'Respuestas de formulario 1'!$E:$E,$A5)>0,1,0) -> 0 | E5: =IF(COUNTIFS('Respuestas de formulario 1'!$D:$D,E$4,'Respuestas de formulario 1'!$E:$E,$A5)>0,1,0) -> 0 | F5: =IF(COUNTIFS('Respuestas de formulario 1'!$D:$D,F$4,'Respuestas de formulario 1'!$E:$E,$A5)>0,1,0) -> 0 | G5: =IF(COUNTIFS('Respuestas de formulario 1'!$D:$D,G$4,'Respuestas de formulario 1'!$E:$E,$A5)>0,1,0) -> 0 | H5: =IF(COUNTIFS('Respuestas de formulario 1'!$D:$D,H$4,'Respuestas de formulario 1'!$E:$E,$A5)>0,1,0) -> 0 | I5: =IF(COUNTIFS('Respuestas de formulario 1'!$D:$D,I$4,'Respuestas de formulario 1'!$E:$E,$A5)>0,1,0) -> 0 | ... K5: =IF(COUNTIFS('Respuestas de formulario 1'!$D:$D,K$4,'Respuestas de formulario 1'!$E:$E,$A5)>0,1,0) -> 0 | L5: =SUM(B5:K5) -> 1 | M5: =COUNT($B$4:$K$4)-L5 -> 9
A6: fernando ariza cubides | B6: =IF(COUNTIFS('Respuestas de formulario 1'!$D:$D,B$4,'Respuestas de formulario 1'!$E:$E,$A6)>0,1,0) -> 1 | C6: =IF(COUNTIFS('Respuestas de formulario 1'!$D:$D,C$4,'Respuestas de formulario 1'!$E:$E,$A6)>0,1,0) -> 1 | D6: =IF(COUNTIFS('Respuestas de formulario 1'!$D:$D,D$4,'Respuestas de formulario 1'!$E:$E,$A6)>0,1,0) -> 1 | E6: =IF(COUNTIFS('Respuestas de formulario 1'!$D:$D,E$4,'Respuestas de formulario 1'!$E:$E,$A6)>0,1,0) -> 1 | F6: =IF(COUNTIFS('Respuestas de formulario 1'!$D:$D,F$4,'Respuestas de formulario 1'!$E:$E,$A6)>0,1,0) -> 1 | G6: =IF(COUNTIFS('Respuestas de formulario 1'!$D:$D,G$4,'Respuestas de formulario 1'!$E:$E,$A6)>0,1,0) -> 1 | H6: =IF(COUNTIFS('Respuestas de formulario 1'!$D:$D,H$4,'Respuestas de formulario 1'!$E:$E,$A6)>0,1,0) -> 1 | I6: =IF(COUNTIFS('Respuestas de formulario 1'!$D:$D,I$4,'Respuestas de formulario 1'!$E:$E,$A6)>0,1,0) -> 0 | ... K6: =IF(COUNTIFS('Respuestas de formulario 1'!$D:$D,K$4,'Respuestas de formulario 1'!$E:$E,$A6)>0,1,0) -> 1 | L6: =SUM(B6:K6) -> 9 | M6: =COUNT($B$4:$K$4)-L6 -> 1
A7: nidya ivett avella mariño | B7: =IF(COUNTIFS('Respuestas de formulario 1'!$D:$D,B$4,'Respuestas de formulario 1'!$E:$E,$A7)>0,1,0) -> 1 | C7: =IF(COUNTIFS('Respuestas de formulario 1'!$D:$D,C$4,'Respuestas de formulario 1'!$E:$E,$A7)>0,1,0) -> 1 | D7: =IF(COUNTIFS('Respuestas de formulario 1'!$D:$D,D$4,'Respuestas de formulario 1'!$E:$E,$A7)>0,1,0) -> 1 | E7: =IF(COUNTIFS('Respuestas de formulario 1'!$D:$D,E$4,'Respuestas de formulario 1'!$E:$E,$A7)>0,1,0) -> 1 | F7: =IF(COUNTIFS('Respuestas de formulario 1'!$D:$D,F$4,'Respuestas de formulario 1'!$E:$E,$A7)>0,1,0) -> 0 | G7: =IF(COUNTIFS('Respuestas de formulario 1'!$D:$D,G$4,'Respuestas de formulario 1'!$E:$E,$A7)>0,1,0) -> 0 | H7: =IF(COUNTIFS('Respuestas de formulario 1'!$D:$D,H$4,'Respuestas de formulario 1'!$E:$E,$A7)>0,1,0) -> 0 | I7: =IF(COUNTIFS('Respuestas de formulario 1'!$D:$D,I$4,'Respuestas de formulario 1'!$E:$E,$A7)>0,1,0) -> 1 | ... K7: =IF(COUNTIFS('Respuestas de formulario 1'!$D:$D,K$4,'Respuestas de formulario 1'!$E:$E,$A7)>0,1,0) -> 1 | L7: =SUM(B7:K7) -> 7 | M7: =COUNT($B$4:$K$4)-L7 -> 3
A8: ena yuritze baron lopez | B8: =IF(COUNTIFS('Respuestas de formulario 1'!$D:$D,B$4,'Respuestas de formulario 1'!$E:$E,$A8)>0,1,0) -> 0 | C8: =IF(COUNTIFS('Respuestas de formulario 1'!$D:$D,C$4,'Respuestas de formulario 1'!$E:$E,$A8)>0,1,0) -> 1 | D8: =IF(COUNTIFS('Respuestas de formulario 1'!$D:$D,D$4,'Respuestas de formulario 1'!$E:$E,$A8)>0,1,0) -> 1 | E8: =IF(COUNTIFS('Respuestas de formulario 1'!$D:$D,E$4,'Respuestas de formulario 1'!$E:$E,$A8)>0,1,0) -> 1 | F8: =IF(COUNTIFS('Respuestas de formulario 1'!$D:$D,F$4,'Respuestas de formulario 1'!$E:$E,$A8)>0,1,0) -> 1 | G8: =IF(COUNTIFS('Respuestas de formulario 1'!$D:$D,G$4,'Respuestas de formulario 1'!$E:$E,$A8)>0,1,0) -> 1 | H8: =IF(COUNTIFS('Respuestas de formulario 1'!$D:$D,H$4,'Respuestas de formulario 1'!$E:$E,$A8)>0,1,0) -> 1 | I8: =IF(COUNTIFS('Respuestas de formulario 1'!$D:$D,I$4,'Respuestas de formulario 1'!$E:$E,$A8)>0,1,0) -> 1 | ... K8: =IF(COUNTIFS('Respuestas de formulario 1'!$D:$D,K$4,'Respuestas de formulario 1'!$E:$E,$A8)>0,1,0) -> 1 | L8: =SUM(B8:K8) -> 8 | M8: =COUNT($B$4:$K$4)-L8 -> 2
A9: Sandra Cecilia Bautista Rodriguez | B9: =IF(COUNTIFS('Respuestas de formulario 1'!$D:$D,B$4,'Respuestas de formulario 1'!$E:$E,$A9)>0,1,0) -> 1 | C9: =IF(COUNTIFS('Respuestas de formulario 1'!$D:$D,C$4,'Respuestas de formulario 1'!$E:$E,$A9)>0,1,0) -> 1 | D9: =IF(COUNTIFS('Respuestas de formulario 1'!$D:$D,D$4,'Respuestas de formulario 1'!$E:$E,$A9)>0,1,0) -> 1 | E9: =IF(COUNTIFS('Respuestas de formulario 1'!$D:$D,E$4,'Respuestas de formulario 1'!$E:$E,$A9)>0,1,0) -> 1 | F9: =IF(COUNTIFS('Respuestas de formulario 1'!$D:$D,F$4,'Respuestas de formulario 1'!$E:$E,$A9)>0,1,0) -> 1 | G9: =IF(COUNTIFS('Respuestas de formulario 1'!$D:$D,G$4,'Respuestas de formulario 1'!$E:$E,$A9)>0,1,0) -> 1 | H9: =IF(COUNTIFS('Respuestas de formulario 1'!$D:$D,H$4,'Respuestas de formulario 1'!$E:$E,$A9)>0,1,0) -> 1 | I9: =IF(COUNTIFS('Respuestas de formulario 1'!$D:$D,I$4,'Respuestas de formulario 1'!$E:$E,$A9)>0,1,0) -> 1 | ... K9: =IF(COUNTIFS('Respuestas de formulario 1'!$D:$D,K$4,'Respuestas de formulario 1'!$E:$E,$A9)>0,1,0) -> 1 | L9: =SUM(B9:K9) -> 9 | M9: =COUNT($B$4:$K$4)-L9 -> 1
A10: ANGIE LORENA BAZURTO LOZADA | B10: =IF(COUNTIFS('Respuestas de formulario 1'!$D:$D,B$4,'Respuestas de formulario 1'!$E:$E,$A10)>0,1,0) -> 1 | C10: =IF(COUNTIFS('Respuestas de formulario 1'!$D:$D,C$4,'Respuestas de formulario 1'!$E:$E,$A10)>0,1,0) -> 1 | D10: =IF(COUNTIFS('Respuestas de formulario 1'!$D:$D,D$4,'Respuestas de formulario 1'!$E:$E,$A10)>0,1,0) -> 1 | E10: =IF(COUNTIFS('Respuestas de formulario 1'!$D:$D,E$4,'Respuestas de formulario 1'!$E:$E,$A10)>0,1,0) -> 1 | F10: =IF(COUNTIFS('Respuestas de formulario 1'!$D:$D,F$4,'Respuestas de formulario 1'!$E:$E,$A10)>0,1,0) -> 1 | G10: =IF(COUNTIFS('Respuestas de formulario 1'!$D:$D,G$4,'Respuestas de formulario 1'!$E:$E,$A10)>0,1,0) -> 1 | H10: =IF(COUNTIFS('Respuestas de formulario 1'!$D:$D,H$4,'Respuestas de formulario 1'!$E:$E,$A10)>0,1,0) -> 1 | I10: =IF(COUNTIFS('Respuestas de formulario 1'!$D:$D,I$4,'Respuestas de formulario 1'!$E:$E,$A10)>0,1,0) -> 1 | ... K10: =IF(COUNTIFS('Respuestas de formulario 1'!$D:$D,K$4,'Respuestas de formulario 1'!$E:$E,$A10)>0,1,0) -> 1 | L10: =SUM(B10:K10) -> 10 | M10: =COUNT($B$4:$K$4)-L10 -> 0
A11: jenny paola beltran beltran | B11: =IF(COUNTIFS('Respuestas de formulario 1'!$D:$D,B$4,'Respuestas de formulario 1'!$E:$E,$A11)>0,1,0) -> 0 | C11: =IF(COUNTIFS('Respuestas de formulario 1'!$D:$D,C$4,'Respuestas de formulario 1'!$E:$E,$A11)>0,1,0) -> 0 | D11: =IF(COUNTIFS('Respuestas de formulario 1'!$D:$D,D$4,'Respuestas de formulario 1'!$E:$E,$A11)>0,1,0) -> 0 | E11: =IF(COUNTIFS('Respuestas de formulario 1'!$D:$D,E$4,'Respuestas de formulario 1'!$E:$E,$A11)>0,1,0) -> 0 | F11: =IF(COUNTIFS('Respuestas de formulario 1'!$D:$D,F$4,'Respuestas de formulario 1'!$E:$E,$A11)>0,1,0) -> 0 | G11: =IF(COUNTIFS('Respuestas de formulario 1'!$D:$D,G$4,'Respuestas de formulario 1'!$E:$E,$A11)>0,1,0) -> 0 | H11: =IF(COUNTIFS('Respuestas de formulario 1'!$D:$D,H$4,'Respuestas de formulario 1'!$E:$E,$A11)>0,1,0) -> 0 | I11: =IF(COUNTIFS('Respuestas de formulario 1'!$D:$D,I$4,'Respuestas de formulario 1'!$E:$E,$A11)>0,1,0) -> 0 | ... K11: =IF(COUNTIFS('Respuestas de formulario 1'!$D:$D,K$4,'Respuestas de formulario 1'!$E:$E,$A11)>0,1,0) -> 0 | L11: =SUM(B11:K11) -> 0 | M11: =COUNT($B$4:$K$4)-L11 -> 10
A12: elias buitrago bolivar | B12: =IF(COUNTIFS('Respuestas de formulario 1'!$D:$D,B$4,'Respuestas de formulario 1'!$E:$E,$A12)>0,1,0) -> 1 | C12: =IF(COUNTIFS('Respuestas de formulario 1'!$D:$D,C$4,'Respuestas de formulario 1'!$E:$E,$A12)>0,1,0) -> 0 | D12: =IF(COUNTIFS('Respuestas de formulario 1'!$D:$D,D$4,'Respuestas de formulario 1'!$E:$E,$A12)>0,1,0) -> 0 | E12: =IF(COUNTIFS('Respuestas de formulario 1'!$D:$D,E$4,'Respuestas de formulario 1'!$E:$E,$A12)>0,1,0) -> 0 | F12: =IF(COUNTIFS('Respuestas de formulario 1'!$D:$D,F$4,'Respuestas de formulario 1'!$E:$E,$A12)>0,1,0) -> 0 | G12: =IF(COUNTIFS('Respuestas de formulario 1'!$D:$D,G$4,'Respuestas de formulario 1'!$E:$E,$A12)>0,1,0) -> 0 | H12: =IF(COUNTIFS('Respuestas de formulario 1'!$D:$D,H$4,'Respuestas de formulario 1'!$E:$E,$A12)>0,1,0) -> 0 | I12: =IF(COUNTIFS('Respuestas de formulario 1'!$D:$D,I$4,'Respuestas de formulario 1'!$E:$E,$A12)>0,1,0) -> 0 | ... K12: =IF(COUNTIFS('Respuestas de formulario 1'!$D:$D,K$4,'Respuestas de formulario 1'!$E:$E,$A12)>0,1,0) -> 0 | L12: =SUM(B12:K12) -> 1 | M12: =COUNT($B$4:$K$4)-L12 -> 9
A13: dayana calderon manrique | B13: =IF(COUNTIFS('Respuestas de formulario 1'!$D:$D,B$4,'Respuestas de formulario 1'!$E:$E,$A13)>0,1,0) -> 1 | C13: =IF(COUNTIFS('Respuestas de formulario 1'!$D:$D,C$4,'Respuestas de formulario 1'!$E:$E,$A13)>0,1,0) -> 1 | D13: =IF(COUNTIFS('Respuestas de formulario 1'!$D:$D,D$4,'Respuestas de formulario 1'!$E:$E,$A13)>0,1,0) -> 1 | E13: =IF(COUNTIFS('Respuestas de formulario 1'!$D:$D,E$4,'Respuestas de formulario 1'!$E:$E,$A13)>0,1,0) -> 1 | F13: =IF(COUNTIFS('Respuestas de formulario 1'!$D:$D,F$4,'Respuestas de formulario 1'!$E:$E,$A13)>0,1,0) -> 1 | G13: =IF(COUNTIFS('Respuestas de formulario 1'!$D:$D,G$4,'Respuestas de formulario 1'!$E:$E,$A13)>0,1,0) -> 1 | H13: =IF(COUNTIFS('Respuestas de formulario 1'!$D:$D,H$4,'Respuestas de formulario 1'!$E:$E,$A13)>0,1,0) -> 1 | I13: =IF(COUNTIFS('Respuestas de formulario 1'!$D:$D,I$4,'Respuestas de formulario 1'!$E:$E,$A13)>0,1,0) -> 1 | ... K13: =IF(COUNTIFS('Respuestas de formulario 1'!$D:$D,K$4,'Respuestas de formulario 1'!$E:$E,$A13)>0,1,0) -> 1 | L13: =SUM(B13:K13) -> 9 | M13: =COUNT($B$4:$K$4)-L13 -> 1
A14: mauricio castaño arcila | B14: =IF(COUNTIFS('Respuestas de formulario 1'!$D:$D,B$4,'Respuestas de formulario 1'!$E:$E,$A14)>0,1,0) -> 1 | C14: =IF(COUNTIFS('Respuestas de formulario 1'!$D:$D,C$4,'Respuestas de formulario 1'!$E:$E,$A14)>0,1,0) -> 1 | D14: =IF(COUNTIFS('Respuestas de formulario 1'!$D:$D,D$4,'Respuestas de formulario 1'!$E:$E,$A14)>0,1,0) -> 1 | E14: =IF(COUNTIFS('Respuestas de formulario 1'!$D:$D,E$4,'Respuestas de formulario 1'!$E:$E,$A14)>0,1,0) -> 1 | F14: =IF(COUNTIFS('Respuestas de formulario 1'!$D:$D,F$4,'Respuestas de formulario 1'!$E:$E,$A14)>0,1,0) -> 1 | G14: =IF(COUNTIFS('Respuestas de formulario 1'!$D:$D,G$4,'Respuestas de formulario 1'!$E:$E,$A14)>0,1,0) -> 1 | H14: =IF(COUNTIFS('Respuestas de formulario 1'!$D:$D,H$4,'Respuestas de formulario 1'!$E:$E,$A14)>0,1,0) -> 1 | I14: =IF(COUNTIFS('Respuestas de formulario 1'!$D:$D,I$4,'Respuestas de formulario 1'!$E:$E,$A14)>0,1,0) -> 1 | ... K14: =IF(COUNTIFS('Respuestas de formulario 1'!$D:$D,K$4,'Respuestas de formulario 1'!$E:$E,$A14)>0,1,0) -> 1 | L14: =SUM(B14:K14) -> 10 | M14: =COUNT($B$4:$K$4)-L14 -> 0
A15: miguel david castillo alarcon | B15: =IF(COUNTIFS('Respuestas de formulario 1'!$D:$D,B$4,'Respuestas de formulario 1'!$E:$E,$A15)>0,1,0) -> 1 | C15: =IF(COUNTIFS('Respuestas de formulario 1'!$D:$D,C$4,'Respuestas de formulario 1'!$E:$E,$A15)>0,1,0) -> 1 | D15: =IF(COUNTIFS('Respuestas de formulario 1'!$D:$D,D$4,'Respuestas de formulario 1'!$E:$E,$A15)>0,1,0) -> 1 | E15: =IF(COUNTIFS('Respuestas de formulario 1'!$D:$D,E$4,'Respuestas de formulario 1'!$E:$E,$A15)>0,1,0) -> 1 | F15: =IF(COUNTIFS('Respuestas de formulario 1'!$D:$D,F$4,'Respuestas de formulario 1'!$E:$E,$A15)>0,1,0) -> 1 | G15: =IF(COUNTIFS('Respuestas de formulario 1'!$D:$D,G$4,'Respuestas de formulario 1'!$E:$E,$A15)>0,1,0) -> 1 | H15: =IF(COUNTIFS('Respuestas de formulario 1'!$D:$D,H$4,'Respuestas de formulario 1'!$E:$E,$A15)>0,1,0) -> 1 | I15: =IF(COUNTIFS('Respuestas de formulario 1'!$D:$D,I$4,'Respuestas de formulario 1'!$E:$E,$A15)>0,1,0) -> 1 | ... K15: =IF(COUNTIFS('Respuestas de formulario 1'!$D:$D,K$4,'Respuestas de formulario 1'!$E:$E,$A15)>0,1,0) -> 1 | L15: =SUM(B15:K15) -> 9 | M15: =COUNT($B$4:$K$4)-L15 -> 1
A16: oscar mauricio cepeda valero | B16: =IF(COUNTIFS('Respuestas de formulario 1'!$D:$D,B$4,'Respuestas de formulario 1'!$E:$E,$A16)>0,1,0) -> 1 | C16: =IF(COUNTIFS('Respuestas de formulario 1'!$D:$D,C$4,'Respuestas de formulario 1'!$E:$E,$A16)>0,1,0) -> 1 | D16: =IF(COUNTIFS('Respuestas de formulario 1'!$D:$D,D$4,'Respuestas de formulario 1'!$E:$E,$A16)>0,1,0) -> 1 | E16: =IF(COUNTIFS('Respuestas de formulario 1'!$D:$D,E$4,'Respuestas de formulario 1'!$E:$E,$A16)>0,1,0) -> 1 | F16: =IF(COUNTIFS('Respuestas de formulario 1'!$D:$D,F$4,'Respuestas de formulario 1'!$E:$E,$A16)>0,1,0) -> 1 | G16: =IF(COUNTIFS('Respuestas de formulario 1'!$D:$D,G$4,'Respuestas de formulario 1'!$E:$E,$A16)>0,1,0) -> 1 | H16: =IF(COUNTIFS('Respuestas de formulario 1'!$D:$D,H$4,'Respuestas de formulario 1'!$E:$E,$A16)>0,1,0) -> 1 | I16: =IF(COUNTIFS('Respuestas de formulario 1'!$D:$D,I$4,'Respuestas de formulario 1'!$E:$E,$A16)>0,1,0) -> 1 | ... K16: =IF(COUNTIFS('Respuestas de formulario 1'!$D:$D,K$4,'Respuestas de formulario 1'!$E:$E,$A16)>0,1,0) -> 0 | L16: =SUM(B16:K16) -> 9 | M16: =COUNT($B$4:$K$4)-L16 -> 1
... A56: JORGE LUIS YARCE TAMAYO | B56: =IF(COUNTIFS('Respuestas de formulario 1'!$D:$D,B$4,'Respuestas de formulario 1'!$E:$E,$A56)>0,1,0) -> 0 | C56: =IF(COUNTIFS('Respuestas de formulario 1'!$D:$D,C$4,'Respuestas de formulario 1'!$E:$E,$A56)>0,1,0) -> 0 | D56: =IF(COUNTIFS('Respuestas de formulario 1'!$D:$D,D$4,'Respuestas de formulario 1'!$E:$E,$A56)>0,1,0) -> 0 | E56: =IF(COUNTIFS('Respuestas de formulario 1'!$D:$D,E$4,'Respuestas de formulario 1'!$E:$E,$A56)>0,1,0) -> 1 | F56: =IF(COUNTIFS('Respuestas de formulario 1'!$D:$D,F$4,'Respuestas de formulario 1'!$E:$E,$A56)>0,1,0) -> 1 | G56: =IF(COUNTIFS('Respuestas de formulario 1'!$D:$D,G$4,'Respuestas de formulario 1'!$E:$E,$A56)>0,1,0) -> 0 | H56: =IF(COUNTIFS('Respuestas de formulario 1'!$D:$D,H$4,'Respuestas de formulario 1'!$E:$E,$A56)>0,1,0) -> 0 | I56: =IF(COUNTIFS('Respuestas de formulario 1'!$D:$D,I$4,'Respuestas de formulario 1'!$E:$E,$A56)>0,1,0) -> 1 | ... K56: =IF(COUNTIFS('Respuestas de formulario 1'!$D:$D,K$4,'Respuestas de formulario 1'!$E:$E,$A56)>0,1,0) -> 0 | L56: =SUM(B56:K56) -> 3 | M56: =COUNT($B$4:$K$4)-L56 -> 7
A57: Asistentes NO inscritos en plataforma
A58: Juan Manuel Méndez Guzmán | B58: =IF(COUNTIFS('Respuestas de formulario 1'!$D:$D,B$4,'Respuestas de formulario 1'!$E:$E,"NO INSCRITO: "&$A58)>0,1,0) -> 1 | C58: =IF(COUNTIFS('Respuestas de formulario 1'!$D:$D,C$4,'Respuestas de formulario 1'!$E:$E,"NO INSCRITO: "&$A58)>0,1,0) -> 1 | D58: =IF(COUNTIFS('Respuestas de formulario 1'!$D:$D,D$4,'Respuestas de formulario 1'!$E:$E,"NO INSCRITO: "&$A58)>0,1,0) -> 1 | E58: =IF(COUNTIFS('Respuestas de formulario 1'!$D:$D,E$4,'Respuestas de formulario 1'!$E:$E,"NO INSCRITO: "&$A58)>0,1,0) -> 1 | F58: =IF(COUNTIFS('Respuestas de formulario 1'!$D:$D,F$4,'Respuestas de formulario 1'!$E:$E,"NO INSCRITO: "&$A58)>0,1,0) -> 1 | G58: =IF(COUNTIFS('Respuestas de formulario 1'!$D:$D,G$4,'Respuestas de formulario 1'!$E:$E,"NO INSCRITO: "&$A58)>0,1,0) -> 1 | H58: =IF(COUNTIFS('Respuestas de formulario 1'!$D:$D,H$4,'Respuestas de formulario 1'!$E:$E,"NO INSCRITO: "&$A58)>0,1,0) -> 0 | I58: =IF(COUNTIFS('Respuestas de formulario 1'!$D:$D,I$4,'Respuestas de formulario 1'!$E:$E,"NO INSCRITO: "&$A58)>0,1,0) -> 0 | ... K58: =IF(COUNTIFS('Respuestas de formulario 1'!$D:$D,K$4,'Respuestas de formulario 1'!$E:$E,"NO INSCRITO: "&$A58)>0,1,0) -> 0 | L58: =SUM(B58:K58) -> 6 | M58: =COUNT($B$4:$K$4)-L58 -> 4
A59: Camilo Andres Pulido Laverde | B59: =IF(COUNTIFS('Respuestas de formulario 1'!$D:$D,B$4,'Respuestas de formulario 1'!$E:$E,"NO INSCRITO: "&$A59)>0,1,0) -> 1 | C59: =IF(COUNTIFS('Respuestas de formulario 1'!$D:$D,C$4,'Respuestas de formulario 1'!$E:$E,"NO INSCRITO: "&$A59)>0,1,0) -> 1 | D59: =IF(COUNTIFS('Respuestas de formulario 1'!$D:$D,D$4,'Respuestas de formulario 1'!$E:$E,"NO INSCRITO: "&$A59)>0,1,0) -> 0 | E59: =IF(COUNTIFS('Respuestas de formulario 1'!$D:$D,E$4,'Respuestas de formulario 1'!$E:$E,"NO INSCRITO: "&$A59)>0,1,0) -> 0 | F59: =IF(COUNTIFS('Respuestas de formulario 1'!$D:$D,F$4,'Respuestas de formulario 1'!$E:$E,"NO INSCRITO: "&$A59)>0,1,0) -> 0 | G59: =IF(COUNTIFS('Respuestas de formulario 1'!$D:$D,G$4,'Respuestas de formulario 1'!$E:$E,"NO INSCRITO: "&$A59)>0,1,0) -> 0 | H59: =IF(COUNTIFS('Respuestas de formulario 1'!$D:$D,H$4,'Respuestas de formulario 1'!$E:$E,"NO INSCRITO: "&$A59)>0,1,0) -> 0 | I59: =IF(COUNTIFS('Respuestas de formulario 1'!$D:$D,I$4,'Respuestas de formulario 1'!$E:$E,"NO INSCRITO: "&$A59)>0,1,0) -> 0 | ... K59: =IF(COUNTIFS('Respuestas de formulario 1'!$D:$D,K$4,'Respuestas de formulario 1'!$E:$E,"NO INSCRITO: "&$A59)>0,1,0) -> 0 | L59: =SUM(B59:K59) -> 2 | M59: =COUNT($B$4:$K$4)-L59 -> 8

Sheet Grupos - Producto
A1: No. | B1: DOCENTE | C1: Grupo
A2: 1 | B2: Erika Alexandra Torrado Briceño | C2: 1
A3: 2 | B3: Jimmy Alexander Vega Florez | C3: 2
A4: 3 | B4: Iris Leticia Fernandez Marin | C4: 3
A5: 4 | B5: Monica Alejandra Rodriguez | C5: 3
A6: 5 | B6: María Paz Guerrero Flórez | C6: 4
A7: 6 | B7: Henry Antonio Romero Leon | C7: 5
A8: 7 | B8: Angie Lorena Bazurto Lozada | C8: 6
A9: 8 | B9: Azeneth Florez Gutierrez | C9: 6
A10: 9 | B10: Fernando Ariza Cubides | C10: 7
A11: 10 | B11: Oscar Javier Medina González | C11: 7
A12: 11 | B12: Constanza Beatriz Perez Martelo | C12: 8
A13: 12 | B13: Sandra Cecilia Bautista Rodriguez | C13: 8
... A36: 35 | B36: William Daniel Moscoso Barrera | C36: 23
A37: 36 | B37: Andres Felipe Niño Sanabria
A38: 37 | B38: Angie Tatiana Moreno Rodriguez
A39: 38 | B39: Cesar Augusto Giraldo Duque
A40: 39 | B40: Claudia Palacio Vasco
A41: 40 | B41: Diego Alfonso Sánchez Mora
A42: 41 | B42: Diego Fernando Sanchez Beltran
A43: 42 | B43: Edgar Stefan Orellanos Chaparro
A44: 43 | B44: Elias Buitrago Bolivar
A45: 44 | B45: Ferney Alexander Perez Parada
A46: 45 | B46: German Alberto Corredor Marin
A47: 46 | B47: Gian Andrei Gomez Celis
A48: 47 | B48: Hernan Dario Granda
... A55: 54 | B55: Sandra Milena Pulido Cuervo

Sheet inscritos en plataforma
A1: Nombre | B1: Apellido
A2: juan manuel | B2: anzola lagos
A3: fernando | B3: ariza cubides
A4: nidya ivett | B4: avella mariño
A5: ena yuritze | B5: baron lopez
A6: Sandra Cecilia | B6: Bautista Rodriguez
A7: ANGIE LORENA | B7: BAZURTO LOZADA
A8: jenny paola | B8: beltran beltran
A9: elias | B9: buitrago bolivar
A10: dayana | B10: calderon manrique
A11: mauricio | B11: castaño arcila
A12: miguel david | B12: castillo alarcon
... A54: JORGE LUIS | B54: YARCE TAMAYO

Sheet Respuestas de formulario 1
A1: Registro | B1: Nombre Completo | C1: Facultad | D1: Día (serial) | E1: Inscrito (plataforma)
A2: 46175.42 | B2: Andrés Felipe NIño Sanabria | C2: Escuela de Artes | D2: 46175 | E2: andres felipe niño sanabria
A3: 46175.42 | B3: Jhonatan Steven Mora Rodríguez | C3: Facultad de Ingeniería y Ciencias Básicas | D3: 46175 | E3: jhonatan steven mora rodriguez
A4: 46175.42 | B4: Dayana Calderon Manrique | C4: FACULTAD DE INGENIERÍA Y CIENCIAS BÁSICAS | D4: 46175 | E4: dayana calderon manrique
A5: 46175.42 | B5: Jimmy Alexander Vega Florez | C5: Facultad de Ingeniería y Ciencias Básicas | D5: 46175 | E5: Jimmy Alexander Vega Florez
A6: 46175.42 | B6: Fernando Ariza Cubides | C6: FICB | D6: 46175 | E6: fernando ariza cubides
A7: 46175.42 | B7: Azeneth Flórez Gutiérrez | C7: Contaduría Pública | D7: 46175 | E7: azeneth florez gutierrez
A8: 46175.42 | B8: Henry Antonio Romero León | C8: Facultad de Ciencias Empresariales, Jurídicas y de Comunicacion Estratégica | D8: 46175 | E8: henry antonio romero leon
A9: 46175.42 | B9: Jonnthan López Hurtado | C9: Facultad de Ciencias Empresariales, Jurídicas y de Comunicación Estratégica | D9: 46175 | E9: JONNATHAN LÓPEZ HURTADO
A10: 46175.42 | B10: Luis Fernando Jimenez Monsalve | C10: FICB | D10: 46175 | E10: luis fernando jimenez monsalve
A11: 46175.421 | B11: Jorge Enrique Muñoz Barragán | C11: FICB | D11: 46175 | E11: jorge enrique muñoz barragan
A12: 46175.421 | B12: Miguel David Castillo Alarcón | C12: FCEJCE | D12: 46175 | E12: miguel david castillo alarcon
A13: 46175.421 | B13: Víctor Felipe Vallejo Rodríguez | C13: Facultad de Ingeniería y Ciencias Básicas | D13: 46175 | E13: VÍCTOR FELIPE VALLEJO RODRÍGUEZ
... A277: 46196.495 | B277: Jonnathan López Hurtado | C277: Facultad de Ciencias Empresariales, Jurídicas y de Comunicación Estratégica | D277: 46196 | E277: JONNATHAN LÓPEZ HURTADO
A278: 46196.496 | B278: ANYI LORENA BAZURTO L | C278: 39577091 | D278: 46196 | E278: ANGIE LORENA BAZURTO LOZADA
A279: 46196.497 | B279: MARIA ISABEL PÉREZ CAMACHO | C279: FICB | D279: 46196 | E279: maria isabel perez camacho
A280: 46196.497 | B280: Carlos Andrés oliveros aya | C280: Derecho | D280: 46196 | E280: CARLOS ANDRÉS OLIVEROS AYA
A281: 46196.5 | B281: Claudia Palacio Vasco | C281: Escuela de Estudios Transversales | D281: 46196 | E281: claudia palacio vasco
A282: 46196.5 | B282: Jorge Enrique Muñoz Barragán | C282: FICB / Ingeniería Ambiental | D282: 46196 | E282: jorge enrique muñoz barragan
A283: 46196.501 | B283: Erika Torrado | C283: Facultad de Ingenieria y Ciencias Basicas | D283: 46196 | E283: Erika Alexandra Torrado Briceño
A284: 46196.501 | B284: Alejandro David Charris Florez | C284: Derecho | D284: 46196 | E284: alejandro david charris florez
A285: 46196.501 | B285: JIMMY ALEXANDER VEGA FLOREZ | C285: FACULTAD DE INGENIERIA | D285: 46196 | E285: Jimmy Alexander Vega Florez
A286: 46196.501 | B286: Jhonatan Steven Mora Rodríguez | C286: Facultad de Ciencias Básicas | D286: 46196 | E286: jhonatan steven mora rodriguez
A287: 46196.501 | B287: María Paz Guerrero | C287: Creación Literaria | D287: 46196 | E287: MARÍA PAZ GUERRERO FLÓREZ
A288: 46196.501 | B288: Rebeca Lozano Tabares | C288: FCEJyCE | D288: 46196 | E288: rebeca lozano tabares
A289: 46196.501 | B289: Brigette Yanith Patiño Montaña | C289: Facultad de Ingeniería y Ciencias Básicas. | D289: 46196 | E289: BRIGETTE YANITH PATIÑO MONTAÑA
A290: 46196.501 | B290: Diana Esperanza Oliveros Fortiche | C290: Comunicacion Social y Periodismo | D290: 46196 | E290: Diana Esperanza Oliveros Fortiche
... A321: 46197.521 | B321: Jhonatan Steven Mora Rodríguez | C321: Facultad de Ingeniera y Ciencias Básicas | D321: 46197 | E321: jhonatan steven mora rodriguez
A322: 46197.521 | B322: ANYI LORENA BAZURTO LOZADA | C322: 39577091 | D322: 46197 | E322: ANGIE LORENA BAZURTO LOZADA
A323: 46197.521 | B323: Víctor Felipe Vallejo Rodríguez | C323: Facultad de Ingeniería y Ciencias Básicas | D323: 46197 | E323: VÍCTOR FELIPE VALLEJO RODRÍGUEZ
A324: 46197.521 | B324: Oscar Javier Medina González | C324: Ficb | D324: 46197 | E324: OSCAR JAVIER MEDINA GONZÁLEZ
A325: 46197.521 | B325: Luis Fernando Jimenez Monsalve | C325: Industrial | D325: 46197 | E325: luis fernando jimenez monsalve
A326: 46197.522 | B326: MARÍA ISABEL PÉREZ CAMACHO | C326: FICB | D326: 46197 | E326: maria isabel perez camacho
A327: 46197.522 | B327: Diana Oliveros Fortiche | C327: Comunicación Social y Periodismo | D327: 46197 | E327: Diana Esperanza Oliveros Fortiche
A328: 46197.522 | B328: Rebeca Lozano Tabares | C328: FCEJyCE | D328: 46197 | E328: rebeca lozano tabares
A329: 46197.522 | B329: ANYI LORENA BAZURTO L | C329: ADMÓN DE EMPRESAS | D329: 46197 | E329: ANGIE LORENA BAZURTO LOZADA
A330: 46197.522 | B330: Nidya Ivett Avella Mariño | C330: Escuela de Salud, Cuidado y Protección Social - Programa de Trabajo Social | D330: 46197 | E330: nidya ivett avella mariño
A331: 46197.522 | B331: Azeneth Flórez Gutiérrez | C331: FCEJCE - Contaduría Pública | D331: 46197 | E331: azeneth florez gutierrez
A332: 46197.523 | B332: Oscar Mauricio Cepeda Valero | C332: FICB | D332: 46197 | E332: oscar mauricio cepeda valero
A333: 46197.523 | B333: JIMMY ALEXANDER VEGA FLOREZ | C333: FACULTAD DE INGENIERIA Y CIENCIAS BASICAS | D333: 46197 | E333: Jimmy Alexander Vega Florez
...
